Workbook

Sheet Data
A1: date | B1: store | C1: item | D1: sales | F1: Missing Data Check
A2: 41275 | B2: 1 | C2: 1 | D2: 13 | F2: =COUNTBLANK(A1:D9131) -> 0
A3: 41276 | B3: 1 | C3: 1 | D3: 11
A4: 41277 | B4: 1 | C4: 1 | D4: 14
A5: 41278 | B5: 1 | C5: 1 | D5: 13
A6: 41279 | B6: 1 | C6: 1 | D6: 10
A7: 41280 | B7: 1 | C7: 1 | D7: 12
A8: 41281 | B8: 1 | C8: 1 | D8: 10
A9: 41282 | B9: 1 | C9: 1 | D9: 9
A10: 41283 | B10: 1 | C10: 1 | D10: 12
A11: 41284 | B11: 1 | C11: 1 | D11: 9
A12: 41285 | B12: 1 | C12: 1 | D12: 9
A13: 41286 | B13: 1 | C13: 1 | D13: 7
A14: 41287 | B14: 1 | C14: 1 | D14: 10
... A9131: 43100 | B9131: 1 | C9131: 5 | D9131: 17

Sheet Pivot Table
A1: Sum of sales | B1: Items
A2: Years & Months | B2: 1 | C2: 2 | D2: 3 | E2: 4 | F2: 5
A3: 2013
A4: Jan | B4: 328 | C4: 911 | D4: 547 | E4: 346 | F4: 276
A5: Feb | B5: 322 | C5: 873 | D5: 597 | E5: 340 | F5: 276
A6: Mar | B6: 477 | C6: 1299 | D6: 789 | E6: 467 | F6: 378
A7: Apr | B7: 522 | C7: 1316 | D7: 853 | E7: 514 | F7: 417
A8: May | B8: 531 | C8: 1527 | D8: 993 | E8: 632 | F8: 497
A9: Jun | B9: 627 | C9: 1643 | D9: 996 | E9: 599 | F9: 497
A10: Jul | B10: 661 | C10: 1743 | D10: 1105 | E10: 626 | F10: 519
A11: Aug | B11: 594 | C11: 1591 | D11: 996 | E11: 580 | F11: 508
A12: Sep | B12: 519 | C12: 1353 | D12: 891 | E12: 554 | F12: 430
A13: Oct | B13: 484 | C13: 1330 | D13: 776 | E13: 475 | F13: 426
A14: Nov | B14: 572 | C14: 1427 | D14: 900 | E14: 519 | F14: 422
A15: Dec | B15: 388 | C15: 1023 | D15: 657 | E15: 393 | F15: 356
A16: 2014
A17: Jan | B17: 435 | C17: 1116 | D17: 654 | E17: 366 | F17: 330
A18: Feb | B18: 405 | C18: 1135 | D18: 674 | E18: 415 | F18: 314
A19: Mar | B19: 549 | C19: 1406 | D19: 885 | E19: 524 | F19: 472
A20: Apr | B20: 573 | C20: 1645 | D20: 973 | E20: 631 | F20: 516
A21: May | B21: 651 | C21: 1870 | D21: 1168 | E21: 645 | F21: 598
A22: Jun | B22: 710 | C22: 1849 | D22: 1129 | E22: 693 | F22: 565
A23: Jul | B23: 746 | C23: 2039 | D23: 1204 | E23: 791 | F23: 634
A24: Aug | B24: 671 | C24: 1823 | D24: 1116 | E24: 705 | F24: 589
A25: Sep | B25: 566 | C25: 1539 | D25: 971 | E25: 605 | F25: 473
A26: Oct | B26: 555 | C26: 1506 | D26: 981 | E26: 541 | F26: 465
A27: Nov | B27: 619 | C27: 1595 | D27: 1020 | E27: 640 | F27: 501
A28: Dec | B28: 409 | C28: 1211 | D28: 729 | E28: 474 | F28: 343
A29: 2015
A30: Jan | B30: 428 | C30: 1114 | D30: 719 | E30: 454 | F30: 367
A31: Feb | B31: 399 | C31: 1157 | D31: 670 | E31: 407 | F31: 335
A32: Mar | B32: 552 | C32: 1536 | D32: 908 | E32: 552 | F32: 470
A33: Apr | B33: 652 | C33: 1700 | D33: 1058 | E33: 666 | F33: 495
A34: May | B34: 711 | C34: 1941 | D34: 1236 | E34: 732 | F34: 559
A35: Jun | B35: 748 | C35: 1828 | D35: 1215 | E35: 686 | F35: 614
A36: Jul | B36: 842 | C36: 1967 | D36: 1325 | E36: 783 | F36: 632
A37: Aug | B37: 706 | C37: 1915 | D37: 1178 | E37: 691 | F37: 616
A38: Sep | B38: 678 | C38: 1625 | D38: 1112 | E38: 650 | F38: 511
A39: Oct | B39: 647 | C39: 1622 | D39: 1041 | E39: 604 | F39: 486
A40: Nov | B40: 684 | C40: 1680 | D40: 1059 | E40: 605 | F40: 509
...

Sheet Seasonality Chart
A1: Sum of sales | B1: Items
B2: 1
A3: Years & Months | B3: 2013 | C3: 2014 | D3: 2015 | E3: 2016 | F3: 2017
A4: Jan | B4: 328 | C4: 435 | D4: 428 | E4: 449 | F4: 485
A5: Feb | B5: 322 | C5: 405 | D5: 399 | E5: 450 | F5: 487
A6: Mar | B6: 477 | C6: 549 | D6: 552 | E6: 589 | F6: 561
A7: Apr | B7: 522 | C7: 573 | D7: 652 | E7: 694 | F7: 677
A8: May | B8: 531 | C8: 651 | D8: 711 | E8: 782 | F8: 773
A9: Jun | B9: 627 | C9: 710 | D9: 748 | E9: 790 | F9: 850
A10: Jul | B10: 661 | C10: 746 | D10: 842 | E10: 903 | F10: 873
A11: Aug | B11: 594 | C11: 671 | D11: 706 | E11: 727 | F11: 794
A12: Sep | B12: 519 | C12: 566 | D12: 678 | E12: 709 | F12: 736
A13: Oct | B13: 484 | C13: 555 | D13: 647 | E13: 699 | F13: 660
A14: Nov | B14: 572 | C14: 619 | D14: 684 | E14: 662 | F14: 668
A15: Dec | B15: 388 | C15: 409 | D15: 460 | E15: 496 | F15: 533

Sheet Item 1 3 Month Moving Avg
A1: Month | B1: Actual Sales | C1: 3 Month Moving Average | D1: %Error | E1: Mean Absolute Percentage Error
A2: 41275 | B2: 328 | E2: =AVERAGE(D5:D61) -> 0.189424
A3: 41306 | B3: 322
A4: 41334 | B4: 477 | E4: Demand Variability
A5: 41365 | B5: 522 | C5: =AVERAGE(B2:B4) -> 375.66667 | D5: =ABS(B5-C5)/B5 -> 0.28033206 | E5: =_xlfn.STDEV.S(B2:B61) -> 139.27534
A6: 41395 | B6: 531 | C6: =AVERAGE(B3:B5) -> 440.33333 | D6: =ABS(B6-C6)/B6 -> 0.17074702
A7: 41426 | B7: 627 | C7: =AVERAGE(B4:B6) -> 510 | D7: =ABS(B7-C7)/B7 -> 0.18660287 | E7: Coefficient of Variation
A8: 41456 | B8: 661 | C8: =AVERAGE(B5:B7) -> 560 | D8: =ABS(B8-C8)/B8 -> 0.15279879 | E8: =E5/AVERAGE(B2:B61) -> 0.22914666
A9: 41487 | B9: 594 | C9: =AVERAGE(B6:B8) -> 606.33333 | D9: =ABS(B9-C9)/B9 -> 0.020763187
A10: 41518 | B10: 519 | C10: =AVERAGE(B7:B9) -> 627.33333 | D10: =ABS(B10-C10)/B10 -> 0.20873475 | E10: Safety Stock
A11: 41548 | B11: 484 | C11: =AVERAGE(B8:B10) -> 591.33333 | D11: =ABS(B11-C11)/B11 -> 0.22176309 | E11: =ROUNDUP(1.65*E5*SQRT(0.5),0) -> 163
A12: 41579 | B12: 572 | C12: =AVERAGE(B9:B11) -> 532.33333 | D12: =ABS(B12-C12)/B12 -> 0.069347319
A13: 41609 | B13: 388 | C13: =AVERAGE(B10:B12) -> 525 | D13: =ABS(B13-C13)/B13 -> 0.35309278 | E13: Reorder Point
A14: 41640 | B14: 435 | C14: =AVERAGE(B11:B13) -> 481.33333 | D14: =ABS(B14-C14)/B14 -> 0.10651341 | E14: =ROUNDUP((AVERAGE(B2:B61)*0.5)+E11,0) -> 467
A15: 41671 | B15: 405 | C15: =AVERAGE(B12:B14) -> 465 | D15: =ABS(B15-C15)/B15 -> 0.14814815
A16: 41699 | B16: 549 | C16: =AVERAGE(B13:B15) -> 409.33333 | D16: =ABS(B16-C16)/B16 -> 0.25440194
A17: 41730 | B17: 573 | C17: =AVERAGE(B14:B16) -> 463 | D17: =ABS(B17-C17)/B17 -> 0.19197208
A18: 41760 | B18: 651 | C18: =AVERAGE(B15:B17) -> 509 | D18: =ABS(B18-C18)/B18 -> 0.21812596
A19: 41791 | B19: 710 | C19: =AVERAGE(B16:B18) -> 591 | D19: =ABS(B19-C19)/B19 -> 0.16760563
A20: 41821 | B20: 746 | C20: =AVERAGE(B17:B19) -> 644.66667 | D20: =ABS(B20-C20)/B20 -> 0.13583557
A21: 41852 | B21: 671 | C21: =AVERAGE(B18:B20) -> 702.33333 | D21: =ABS(B21-C21)/B21 -> 0.046696473
A22: 41883 | B22: 566 | C22: =AVERAGE(B19:B21) -> 709 | D22: =ABS(B22-C22)/B22 -> 0.25265018
A23: 41913 | B23: 555 | C23: =AVERAGE(B20:B22) -> 661 | D23: =ABS(B23-C23)/B23 -> 0.19099099
A24: 41944 | B24: 619 | C24: =AVERAGE(B21:B23) -> 597.33333 | D24: =ABS(B24-C24)/B24 -> 0.035002693
A25: 41974 | B25: 409 | C25: =AVERAGE(B22:B24) -> 580 | D25: =ABS(B25-C25)/B25 -> 0.41809291
A26: 42005 | B26: 428 | C26: =AVERAGE(B23:B25) -> 527.66667 | D26: =ABS(B26-C26)/B26 -> 0.23286604
... A61: 43070 | B61: 533 | C61: =AVERAGE(B58:B60) -> 688 | D61: =ABS(B61-C61)/B61 -> 0.29080675
A62: 43101 | C62: =AVERAGE(B59:B61) -> 620.33333

Sheet Item 1 Exponential Smoothing
A1: Month | B1: Actual Sales | C1: 3 Month Moving Average | D1: %Error | E1: Mean Absolute Percentage Error | F1: Dates for Exponential Smoothing | G1: Months being Forecast | H1: Forecast | I1: ETS MAPE | J1: ETS MAPE Average | K1: Original MAPE for OCT, NOV, DEC
A2: 41275 | B2: 328 | E2: =AVERAGE(D5:D61) -> 0.189424 | F2: =DATE(2013,1,1) -> 41275 | G2: October | H2: =_xlfn.FORECAST.ETS(F59, $B$2:$B$58, $F$2:$F$58, 12) -> 710.3918 | I2: =ABS(B59-H2)/B59 -> 0.076351207 | J2: =AVERAGE(I2:I4) -> 0.097805312 | K2: =AVERAGE(D59:D61) -> 0.19908583
A3: 41306 | B3: 322 | F3: 41306 | G3: November | H3: =_xlfn.FORECAST.ETS(F60, $B$2:$B$58, $F$2:$F$58, 12) -> 771.97145 | I3: =ABS(B60-H3)/B60 -> 0.15564588
A4: 41334 | B4: 477 | E4: Demand Variability | F4: 41334 | G4: December | H4: =_xlfn.FORECAST.ETS(F61, $B$2:$B$58, $F$2:$F$58, 12) -> 565.73625 | I4: =ABS(B61-H4)/B61 -> 0.061418848
A5: 41365 | B5: 522 | C5: =AVERAGE(B2:B4) -> 375.66667 | D5: =ABS(B5-C5)/B5 -> 0.28033206 | E5: =_xlfn.STDEV.S(B2:B61) -> 139.27534 | F5: 41365
A6: 41395 | B6: 531 | C6: =AVERAGE(B3:B5) -> 440.33333 | D6: =ABS(B6-C6)/B6 -> 0.17074702 | F6: 41395
A7: 41426 | B7: 627 | C7: =AVERAGE(B4:B6) -> 510 | D7: =ABS(B7-C7)/B7 -> 0.18660287 | E7: Coefficient of Variation | F7: 41426
A8: 41456 | B8: 661 | C8: =AVERAGE(B5:B7) -> 560 | D8: =ABS(B8-C8)/B8 -> 0.15279879 | E8: =E5/AVERAGE(B2:B61) -> 0.22914666 | F8: 41456
A9: 41487 | B9: 594 | C9: =AVERAGE(B6:B8) -> 606.33333 | D9: =ABS(B9-C9)/B9 -> 0.020763187 | F9: 41487
A10: 41518 | B10: 519 | C10: =AVERAGE(B7:B9) -> 627.33333 | D10: =ABS(B10-C10)/B10 -> 0.20873475 | E10: Safety Stock | F10: 41518
A11: 41548 | B11: 484 | C11: =AVERAGE(B8:B10) -> 591.33333 | D11: =ABS(B11-C11)/B11 -> 0.22176309 | E11: =ROUNDUP(1.65*E5*SQRT(0.5),0) -> 163 | F11: 41548
A12: 41579 | B12: 572 | C12: =AVERAGE(B9:B11) -> 532.33333 | D12: =ABS(B12-C12)/B12 -> 0.069347319 | F12: 41579
A13: 41609 | B13: 388 | C13: =AVERAGE(B10:B12) -> 525 | D13: =ABS(B13-C13)/B13 -> 0.35309278 | E13: Reorder Point | F13: 41609
A14: 41640 | B14: 435 | C14: =AVERAGE(B11:B13) -> 481.33333 | D14: =ABS(B14-C14)/B14 -> 0.10651341 | E14: =ROUNDUP((AVERAGE(B2:B61)*0.5)+E11,0) -> 467 | F14: 41640
A15: 41671 | B15: 405 | C15: =AVERAGE(B12:B14) -> 465 | D15: =ABS(B15-C15)/B15 -> 0.14814815 | F15: 41671
A16: 41699 | B16: 549 | C16: =AVERAGE(B13:B15) -> 409.33333 | D16: =ABS(B16-C16)/B16 -> 0.25440194 | F16: 41699
A17: 41730 | B17: 573 | C17: =AVERAGE(B14:B16) -> 463 | D17: =ABS(B17-C17)/B17 -> 0.19197208 | F17: 41730
A18: 41760 | B18: 651 | C18: =AVERAGE(B15:B17) -> 509 | D18: =ABS(B18-C18)/B18 -> 0.21812596 | F18: 41760
A19: 41791 | B19: 710 | C19: =AVERAGE(B16:B18) -> 591 | D19: =ABS(B19-C19)/B19 -> 0.16760563 | F19: 41791
A20: 41821 | B20: 746 | C20: =AVERAGE(B17:B19) -> 644.66667 | D20: =ABS(B20-C20)/B20 -> 0.13583557 | F20: 41821
A21: 41852 | B21: 671 | C21: =AVERAGE(B18:B20) -> 702.33333 | D21: =ABS(B21-C21)/B21 -> 0.046696473 | F21: 41852
A22: 41883 | B22: 566 | C22: =AVERAGE(B19:B21) -> 709 | D22: =ABS(B22-C22)/B22 -> 0.25265018 | F22: 41883
A23: 41913 | B23: 555 | C23: =AVERAGE(B20:B22) -> 661 | D23: =ABS(B23-C23)/B23 -> 0.19099099 | F23: 41913
A24: 41944 | B24: 619 | C24: =AVERAGE(B21:B23) -> 597.33333 | D24: =ABS(B24-C24)/B24 -> 0.035002693 | F24: 41944
A25: 41974 | B25: 409 | C25: =AVERAGE(B22:B24) -> 580 | D25: =ABS(B25-C25)/B25 -> 0.41809291 | F25: 41974
A26: 42005 | B26: 428 | C26: =AVERAGE(B23:B25) -> 527.66667 | D26: =ABS(B26-C26)/B26 -> 0.23286604 | F26: 42005
... A61: 43070 | B61: 533 | C61: =AVERAGE(B58:B60) -> 688 | D61: =ABS(B61-C61)/B61 -> 0.29080675 | F61: 43070
A62: 43101 | C62: =AVERAGE(B59:B61) -> 620.33333 | F62: 43101

Sheet Item 2
A1: Month | B1: Actual Sales | C1: 3 Month Moving Average | D1: %Error | E1: Mean Absolute Percentage Error
A2: 41275 | B2: 911 | E2: =AVERAGE(D5:D61) -> 0.17313147
A3: 41306 | B3: 873
A4: 41334 | B4: 1299 | E4: Demand Variability
A5: 41365 | B5: 1316 | C5: =AVERAGE(B2:B4) -> 1027.6667 | D5: =ABS(B5-C5)/B5 -> 0.21909828 | E5: =_xlfn.STDEV.S(B2:B61) -> 356.84975
A6: 41395 | B6: 1527 | C6: =AVERAGE(B3:B5) -> 1162.6667 | D6: =ABS(B6-C6)/B6 -> 0.23859419
A7: 41426 | B7: 1643 | C7: =AVERAGE(B4:B6) -> 1380.6667 | D7: =ABS(B7-C7)/B7 -> 0.15966728 | E7: Coefficient of Variation
A8: 41456 | B8: 1743 | C8: =AVERAGE(B5:B7) -> 1495.3333 | D8: =ABS(B8-C8)/B8 -> 0.14209218 | E8: =E5/AVERAGE(B2:B61) -> 0.22061808
A9: 41487 | B9: 1591 | C9: =AVERAGE(B6:B8) -> 1637.6667 | D9: =ABS(B9-C9)/B9 -> 0.029331657
A10: 41518 | B10: 1353 | C10: =AVERAGE(B7:B9) -> 1659 | D10: =ABS(B10-C10)/B10 -> 0.22616408 | E10: Safety Stock
A11: 41548 | B11: 1330 | C11: =AVERAGE(B8:B10) -> 1562.3333 | D11: =ABS(B11-C11)/B11 -> 0.17468672 | E11: =ROUNDUP(1.65*E5*SQRT(0.5),0) -> 417
A12: 41579 | B12: 1427 | C12: =AVERAGE(B9:B11) -> 1424.6667 | D12: =ABS(B12-C12)/B12 -> 0.001635132
A13: 41609 | B13: 1023 | C13: =AVERAGE(B10:B12) -> 1370 | D13: =ABS(B13-C13)/B13 -> 0.33919844 | E13: Reorder Point
A14: 41640 | B14: 1116 | C14: =AVERAGE(B11:B13) -> 1260 | D14: =ABS(B14-C14)/B14 -> 0.12903226 | E14: =ROUNDUP((AVERAGE(B2:B61)*0.5)+E11,0) -> 1226
A15: 41671 | B15: 1135 | C15: =AVERAGE(B12:B14) -> 1188.6667 | D15: =ABS(B15-C15)/B15 -> 0.047283407
A16: 41699 | B16: 1406 | C16: =AVERAGE(B13:B15) -> 1091.3333 | D16: =ABS(B16-C16)/B16 -> 0.22380275
A17: 41730 | B17: 1645 | C17: =AVERAGE(B14:B16) -> 1219 | D17: =ABS(B17-C17)/B17 -> 0.25896657
A18: 41760 | B18: 1870 | C18: =AVERAGE(B15:B17) -> 1395.3333 | D18: =ABS(B18-C18)/B18 -> 0.25383244
A19: 41791 | B19: 1849 | C19: =AVERAGE(B16:B18) -> 1640.3333 | D19: =ABS(B19-C19)/B19 -> 0.11285379
A20: 41821 | B20: 2039 | C20: =AVERAGE(B17:B19) -> 1788 | D20: =ABS(B20-C20)/B20 -> 0.12309956
A21: 41852 | B21: 1823 | C21: =AVERAGE(B18:B20) -> 1919.3333 | D21: =ABS(B21-C21)/B21 -> 0.052843299
A22: 41883 | B22: 1539 | C22: =AVERAGE(B19:B21) -> 1903.6667 | D22: =ABS(B22-C22)/B22 -> 0.2369504
A23: 41913 | B23: 1506 | C23: =AVERAGE(B20:B22) -> 1800.3333 | D23: =ABS(B23-C23)/B23 -> 0.19544046
A24: 41944 | B24: 1595 | C24: =AVERAGE(B21:B23) -> 1622.6667 | D24: =ABS(B24-C24)/B24 -> 0.017345873
A25: 41974 | B25: 1211 | C25: =AVERAGE(B22:B24) -> 1546.6667 | D25: =ABS(B25-C25)/B25 -> 0.27718139
A26: 42005 | B26: 1114 | C26: =AVERAGE(B23:B25) -> 1437.3333 | D26: =ABS(B26-C26)/B26 -> 0.29024536
... A61: 43070 | B61: 1475 | C61: =AVERAGE(B58:B60) -> 1877.6667 | D61: =ABS(B61-C61)/B61 -> 0.27299435
A62: 43101 | C62: =AVERAGE(B59:B61) -> 1728.3333

Sheet Item 3
A1: Month | B1: Actual Sales | C1: 3 Month Moving Average | D1: %Error | E1: Mean Absolute Percentage Error
A2: 41275 | B2: 547 | E2: =AVERAGE(D5:D61) -> 0.17857718
A3: 41306 | B3: 597
A4: 41334 | B4: 789 | E4: Demand Variability
A5: 41365 | B5: 853 | C5: =AVERAGE(B2:B4) -> 644.33333 | D5: =ABS(B5-C5)/B5 -> 0.24462681 | E5: =_xlfn.STDEV.S(B2:B61) -> 224.43579
A6: 41395 | B6: 993 | C6: =AVERAGE(B3:B5) -> 746.33333 | D6: =ABS(B6-C6)/B6 -> 0.24840551
A7: 41426 | B7: 996 | C7: =AVERAGE(B4:B6) -> 878.33333 | D7: =ABS(B7-C7)/B7 -> 0.11813922 | E7: Coefficient of Variation
A8: 41456 | B8: 1105 | C8: =AVERAGE(B5:B7) -> 947.33333 | D8: =ABS(B8-C8)/B8 -> 0.14268477 | E8: =E5/AVERAGE(B2:B61) -> 0.2220744
A9: 41487 | B9: 996 | C9: =AVERAGE(B6:B8) -> 1031.3333 | D9: =ABS(B9-C9)/B9 -> 0.035475234
A10: 41518 | B10: 891 | C10: =AVERAGE(B7:B9) -> 1032.3333 | D10: =ABS(B10-C10)/B10 -> 0.15862327 | E10: Safety Stock
A11: 41548 | B11: 776 | C11: =AVERAGE(B8:B10) -> 997.33333 | D11: =ABS(B11-C11)/B11 -> 0.28522337 | E11: =ROUNDUP(1.65*E5*SQRT(0.5),0) -> 262
A12: 41579 | B12: 900 | C12: =AVERAGE(B9:B11) -> 887.66667 | D12: =ABS(B12-C12)/B12 -> 0.013703704
A13: 41609 | B13: 657 | C13: =AVERAGE(B10:B12) -> 855.66667 | D13: =ABS(B13-C13)/B13 -> 0.30238458 | E13: Reorder Point
A14: 41640 | B14: 654 | C14: =AVERAGE(B11:B13) -> 777.66667 | D14: =ABS(B14-C14)/B14 -> 0.18909276 | E14: =ROUNDUP((AVERAGE(B2:B61)*0.5)+E11,0) -> 768
A15: 41671 | B15: 674 | C15: =AVERAGE(B12:B14) -> 737 | D15: =ABS(B15-C15)/B15 -> 0.09347181
A16: 41699 | B16: 885 | C16: =AVERAGE(B13:B15) -> 661.66667 | D16: =ABS(B16-C16)/B16 -> 0.25235405
A17: 41730 | B17: 973 | C17: =AVERAGE(B14:B16) -> 737.66667 | D17: =ABS(B17-C17)/B17 -> 0.24186365
A18: 41760 | B18: 1168 | C18: =AVERAGE(B15:B17) -> 844 | D18: =ABS(B18-C18)/B18 -> 0.27739726
A19: 41791 | B19: 1129 | C19: =AVERAGE(B16:B18) -> 1008.6667 | D19: =ABS(B19-C19)/B19 -> 0.106584
A20: 41821 | B20: 1204 | C20: =AVERAGE(B17:B19) -> 1090 | D20: =ABS(B20-C20)/B20 -> 0.094684385
A21: 41852 | B21: 1116 | C21: =AVERAGE(B18:B20) -> 1167 | D21: =ABS(B21-C21)/B21 -> 0.045698925
A22: 41883 | B22: 971 | C22: =AVERAGE(B19:B21) -> 1149.6667 | D22: =ABS(B22-C22)/B22 -> 0.18400275
A23: 41913 | B23: 981 | C23: =AVERAGE(B20:B22) -> 1097 | D23: =ABS(B23-C23)/B23 -> 0.11824669
A24: 41944 | B24: 1020 | C24: =AVERAGE(B21:B23) -> 1022.6667 | D24: =ABS(B24-C24)/B24 -> 0.0026143791
A25: 41974 | B25: 729 | C25: =AVERAGE(B22:B24) -> 990.66667 | D25: =ABS(B25-C25)/B25 -> 0.35893919
A26: 42005 | B26: 719 | C26: =AVERAGE(B23:B25) -> 910 | D26: =ABS(B26-C26)/B26 -> 0.26564673
... A61: 43070 | B61: 873 | C61: =AVERAGE(B58:B60) -> 1152 | D61: =ABS(B61-C61)/B61 -> 0.31958763
A62: 43101 | C62: =AVERAGE(B59:B61) -> 1043

Sheet Item 4
A1: Month | B1: Actual Sales | C1: 3 Month Moving Average | D1: %Error | E1: Mean Absolute Percentage Error
A2: 41275 | B2: 346 | E2: =AVERAGE(D5:D61) -> 0.17614708
A3: 41306 | B3: 340
A4: 41334 | B4: 467 | E4: Demand Variability
A5: 41365 | B5: 514 | C5: =AVERAGE(B2:B4) -> 384.33333 | D5: =ABS(B5-C5)/B5 -> 0.25226978 | E5: =_xlfn.STDEV.S(B2:B61) -> 133.66207
A6: 41395 | B6: 632 | C6: =AVERAGE(B3:B5) -> 440.33333 | D6: =ABS(B6-C6)/B6 -> 0.30327004
A7: 41426 | B7: 599 | C7: =AVERAGE(B4:B6) -> 537.66667 | D7: =ABS(B7-C7)/B7 -> 0.10239288 | E7: Coefficient of Variation
A8: 41456 | B8: 626 | C8: =AVERAGE(B5:B7) -> 581.66667 | D8: =ABS(B8-C8)/B8 -> 0.070820021 | E8: =E5/AVERAGE(B2:B61) -> 0.22008024
A9: 41487 | B9: 580 | C9: =AVERAGE(B6:B8) -> 619 | D9: =ABS(B9-C9)/B9 -> 0.067241379
A10: 41518 | B10: 554 | C10: =AVERAGE(B7:B9) -> 601.66667 | D10: =ABS(B10-C10)/B10 -> 0.086040915 | E10: Safety Stock
A11: 41548 | B11: 475 | C11: =AVERAGE(B8:B10) -> 586.66667 | D11: =ABS(B11-C11)/B11 -> 0.23508772 | E11: =ROUNDUP(1.65*E5*SQRT(0.5),0) -> 156
A12: 41579 | B12: 519 | C12: =AVERAGE(B9:B11) -> 536.33333 | D12: =ABS(B12-C12)/B12 -> 0.033397559
A13: 41609 | B13: 393 | C13: =AVERAGE(B10:B12) -> 516 | D13: =ABS(B13-C13)/B13 -> 0.3129771 | E13: Reorder Point
A14: 41640 | B14: 366 | C14: =AVERAGE(B11:B13) -> 462.33333 | D14: =ABS(B14-C14)/B14 -> 0.26320583 | E14: =ROUNDUP((AVERAGE(B2:B61)*0.5)+E11,0) -> 460
A15: 41671 | B15: 415 | C15: =AVERAGE(B12:B14) -> 426 | D15: =ABS(B15-C15)/B15 -> 0.026506024
A16: 41699 | B16: 524 | C16: =AVERAGE(B13:B15) -> 391.33333 | D16: =ABS(B16-C16)/B16 -> 0.25318066
A17: 41730 | B17: 631 | C17: =AVERAGE(B14:B16) -> 435 | D17: =ABS(B17-C17)/B17 -> 0.31061807
A18: 41760 | B18: 645 | C18: =AVERAGE(B15:B17) -> 523.33333 | D18: =ABS(B18-C18)/B18 -> 0.18863049
A19: 41791 | B19: 693 | C19: =AVERAGE(B16:B18) -> 600 | D19: =ABS(B19-C19)/B19 -> 0.13419913
A20: 41821 | B20: 791 | C20: =AVERAGE(B17:B19) -> 656.33333 | D20: =ABS(B20-C20)/B20 -> 0.17024863
A21: 41852 | B21: 705 | C21: =AVERAGE(B18:B20) -> 709.66667 | D21: =ABS(B21-C21)/B21 -> 0.0066193853
A22: 41883 | B22: 605 | C22: =AVERAGE(B19:B21) -> 729.66667 | D22: =ABS(B22-C22)/B22 -> 0.20606061
A23: 41913 | B23: 541 | C23: =AVERAGE(B20:B22) -> 700.33333 | D23: =ABS(B23-C23)/B23 -> 0.29451633
A24: 41944 | B24: 640 | C24: =AVERAGE(B21:B23) -> 617 | D24: =ABS(B24-C24)/B24 -> 0.0359375
A25: 41974 | B25: 474 | C25: =AVERAGE(B22:B24) -> 595.33333 | D25: =ABS(B25-C25)/B25 -> 0.2559775
A26: 42005 | B26: 454 | C26: =AVERAGE(B23:B25) -> 551.66667 | D26: =ABS(B26-C26)/B26 -> 0.21512482
... A61: 43070 | B61: 497 | C61: =AVERAGE(B58:B60) -> 676.66667 | D61: =ABS(B61-C61)/B61 -> 0.36150235
A62: 43101 | C62: =AVERAGE(B59:B61) -> 626

Sheet Item 5
A1: Month | B1: Actual Sales | C1: 3 Month Moving Average | D1: %Error | E1: Mean Absolute Percentage Error
A2: 41275 | B2: 276 | E2: =AVERAGE(D5:D61) -> 0.16843451
A3: 41306 | B3: 276
A4: 41334 | B4: 378 | E4: Demand Variability
A5: 41365 | B5: 417 | C5: =AVERAGE(B2:B4) -> 310 | D5: =ABS(B5-C5)/B5 -> 0.25659472 | E5: =_xlfn.STDEV.S(B2:B61) -> 110.76457
A6: 41395 | B6: 497 | C6: =AVERAGE(B3:B5) -> 357 | D6: =ABS(B6-C6)/B6 -> 0.28169014
A7: 41426 | B7: 497 | C7: =AVERAGE(B4:B6) -> 430.66667 | D7: =ABS(B7-C7)/B7 -> 0.13346747 | E7: Coefficient of Variation
A8: 41456 | B8: 519 | C8: =AVERAGE(B5:B7) -> 470.33333 | D8: =ABS(B8-C8)/B8 -> 0.093770071 | E8: =E5/AVERAGE(B2:B61) -> 0.21908271
A9: 41487 | B9: 508 | C9: =AVERAGE(B6:B8) -> 504.33333 | D9: =ABS(B9-C9)/B9 -> 0.0072178478
A10: 41518 | B10: 430 | C10: =AVERAGE(B7:B9) -> 508 | D10: =ABS(B10-C10)/B10 -> 0.18139535 | E10: Safety Stock
A11: 41548 | B11: 426 | C11: =AVERAGE(B8:B10) -> 485.66667 | D11: =ABS(B11-C11)/B11 -> 0.1400626 | E11: =ROUNDUP(1.65*E5*SQRT(0.5),0) -> 130
A12: 41579 | B12: 422 | C12: =AVERAGE(B9:B11) -> 454.66667 | D12: =ABS(B12-C12)/B12 -> 0.077409163
A13: 41609 | B13: 356 | C13: =AVERAGE(B10:B12) -> 426 | D13: =ABS(B13-C13)/B13 -> 0.19662921 | E13: Reorder Point
A14: 41640 | B14: 330 | C14: =AVERAGE(B11:B13) -> 401.33333 | D14: =ABS(B14-C14)/B14 -> 0.21616162 | E14: =ROUNDUP((AVERAGE(B2:B61)*0.5)+E11,0) -> 383
A15: 41671 | B15: 314 | C15: =AVERAGE(B12:B14) -> 369.33333 | D15: =ABS(B15-C15)/B15 -> 0.17622081
A16: 41699 | B16: 472 | C16: =AVERAGE(B13:B15) -> 333.33333 | D16: =ABS(B16-C16)/B16 -> 0.29378531
A17: 41730 | B17: 516 | C17: =AVERAGE(B14:B16) -> 372 | D17: =ABS(B17-C17)/B17 -> 0.27906977
A18: 41760 | B18: 598 | C18: =AVERAGE(B15:B17) -> 434 | D18: =ABS(B18-C18)/B18 -> 0.27424749
A19: 41791 | B19: 565 | C19: =AVERAGE(B16:B18) -> 528.66667 | D19: =ABS(B19-C19)/B19 -> 0.064306785
A20: 41821 | B20: 634 | C20: =AVERAGE(B17:B19) -> 559.66667 | D20: =ABS(B20-C20)/B20 -> 0.11724501
A21: 41852 | B21: 589 | C21: =AVERAGE(B18:B20) -> 599 | D21: =ABS(B21-C21)/B21 -> 0.016977929
A22: 41883 | B22: 473 | C22: =AVERAGE(B19:B21) -> 596 | D22: =ABS(B22-C22)/B22 -> 0.26004228
A23: 41913 | B23: 465 | C23: =AVERAGE(B20:B22) -> 565.33333 | D23: =ABS(B23-C23)/B23 -> 0.21577061
A24: 41944 | B24: 501 | C24: =AVERAGE(B21:B23) -> 509 | D24: =ABS(B24-C24)/B24 -> 0.015968064
A25: 41974 | B25: 343 | C25: =AVERAGE(B22:B24) -> 479.66667 | D25: =ABS(B25-C25)/B25 -> 0.39844509
A26: 42005 | B26: 367 | C26: =AVERAGE(B23:B25) -> 436.33333 | D26: =ABS(B26-C26)/B26 -> 0.18891916
... A61: 43070 | B61: 436 | C61: =AVERAGE(B58:B60) -> 576.33333 | D61: =ABS(B61-C61)/B61 -> 0.32186544
A62: 43101 | C62: =AVERAGE(B59:B61) -> 525.33333

Sheet Summary
A1: Item | B1: Average Monthly Demand | C1: Demand Variability | D1: Coefficient of Variation | E1: Safety Stock | F1: Reorder Point
A2: 1 | B2: =AVERAGE('Item 1 3 Month Moving Avg'!B2:B61) -> 607.8 | C2: ='Item 1 3 Month Moving Avg'!E5 -> 139.27534 | D2: ='Item 1 3 Month Moving Avg'!E8 -> 0.22914666 | E2: ='Item 1 3 Month Moving Avg'!E11 -> 163 | F2: ='Item 1 3 Month Moving Avg'!E14 -> 467
A3: 2 | B3: =AVERAGE('Item 2'!B2:B61) -> 1617.5 | C3: ='Item 2'!E5 -> 356.84975 | D3: ='Item 2'!E8 -> 0.22061808 | E3: ='Item 2'!E11 -> 417 | F3: ='Item 2'!E14 -> 1226
A4: 3 | B4: =AVERAGE('Item 3'!B2:B61) -> 1010.6333 | C4: ='Item 3'!E5 -> 224.43579 | D4: ='Item 3'!E8 -> 0.2220744 | E4: ='Item 3'!E11 -> 262 | F4: ='Item 3'!E14 -> 768
A5: 4 | B5: =AVERAGE('Item 4'!B2:B61) -> 607.33333 | C5: ='Item 4'!E5 -> 133.66207 | D5: ='Item 4'!E8 -> 0.22008024 | E5: ='Item 4'!E11 -> 156 | F5: ='Item 4'!E14 -> 460
A6: 5 | B6: =AVERAGE('Item 5'!B2:B61) -> 505.58333 | C6: ='Item 5'!E5 -> 110.76457 | D6: ='Item 5'!E8 -> 0.21908271 | E6: ='Item 5'!E11 -> 130 | F6: ='Item 5'!E14 -> 383

Sheet Dashboard
A19: Item | B19: Average Monthly Demand | C19: Demand Variability | D19: Coefficient of Variation | E19: Safety Stock | F19: Reorder Point
A20: 1 | B20: 607.8 | C20: 139.27534 | D20: 0.22914666 | E20: 163 | F20: 467
A21: 2 | B21: 1617.5 | C21: 356.84975 | D21: 0.22061808 | E21: 417 | F21: 1226
A22: 3 | B22: 1010.6333 | C22: 224.43579 | D22: 0.2220744 | E22: 262 | F22: 768
A23: 4 | B23: 607.33333 | C23: 133.66207 | D23: 0.22008024 | E23: 156 | F23: 460
A24: 5 | B24: 505.58333 | C24: 110.76457 | D24: 0.21908271 | E24: 130 | F24: 383
A26: Item | B26: MAPE
A27: 1 | B27: ='Item 1 3 Month Moving Avg'!E2 -> 0.189424
A28: 2 | B28: ='Item 2'!E2 -> 0.17313147
A29: 3 | B29: ='Item 3'!E2 -> 0.17857718
A30: 4 | B30: ='Item 4'!E2 -> 0.17614708
A31: 5 | B31: ='Item 5'!E2 -> 0.16843451
A33: Item 1 | B33: Method | C33: Accuracy
B34: 3 Month Moving Average | C34: ='Item 1 Exponential Smoothing'!K2 -> 0.19908583
B35: Exponential Smoothing | C35: ='Item 1 Exponential Smoothing'!J2 -> 0.097805312
